<?xml version="1.0" ?>
<!-- =================================================================================== -->
<!-- |    This document was autogenerated by xacro from /home/juniorsundar/ROS_Workspaces/tii_ws2/src/move_bot_description/urdf/move_bot.xacro | -->
<!-- |    EDITING THIS FILE BY HAND IS NOT RECOMMENDED                                 | -->
<!-- =================================================================================== -->
<!--
  Copyright (c) 2021, PAL Robotics, S.L.
  All rights reserved.

  This work is licensed under the Creative Commons Attribution-NonCommercial-NoDerivs 3.0 Unported License.
  To view a copy of this license, visit http://creativecommons.org/licenses/by-nc-nd/3.0/ or send a letter to
  Creative Commons, 444 Castro Street, Suite 900, Mountain View, California, 94041, USA.
-->
<robot name="move_bot">
    <link name="world" />
    <!-- <xacro:include filename="$(find pmb2_description)/urdf/sensors/imu.urdf.xacro"/> -->
    <material name="Blue">
        <color rgba="0.0 0.0 0.8 1.0" />
    </material>
    <material name="Green">
        <color rgba="0.0 0.8 0.0 1.0" />
    </material>
    <material name="Grey">
        <color rgba="0.7 0.7 0.7 1.0" />
    </material>
    <material name="LightGrey">
        <color rgba="0.9 0.9 0.9 1.0" />
    </material>
    <material name="DarkGrey">
        <color rgba="0.1 0.1 0.1 1.0" />
    </material>
    <material name="Red">
        <color rgba="0.8 0.0 0.0 1.0" />
    </material>
    <material name="White">
        <color rgba="1.0 1.0 1.0 1.0" />
    </material>
    <material name="Yellow">
        <color rgba="0.96 0.88 0.14 1.0" />
    </material>
    <!-- Base footprint -->
    <link name="omni_base_link">
        <inertial>
            <origin rpy="0 0 0" xyz="0.0026742 0.00027459 0.086363" />
            <mass value="34.047" />
            <inertia ixx="0.22777" ixy="0.00035979" ixz="0.00015269" iyy="0.29991" iyz="1.7872E-05" izz="0.46036" />
        </inertial>
        <visual>
            <origin rpy="0 0 0" xyz="0 0 0" />
            <geometry>
                <mesh filename="package://omni_base_description/meshes/base/base_link.stl" />
            </geometry>
            <material name="">
                <color rgba="0.75294 0.75294 0.75294 1" />
            </material>
        </visual>
        <collision>
            <origin rpy="0 0 0" xyz="0 0 0.18925" />
            <geometry>
                <box size="0.717 0.497 0.0845" />
            </geometry>
        </collision>
        <collision>
            <origin rpy="0 0 0" xyz="0 0 0.132" />
            <geometry>
                <box size="0.58 0.39 0.03" />
            </geometry>
        </collision>
        <collision>
            <origin rpy="0 0 0" xyz="0 0 0.0335" />
            <geometry>
                <box size="0.705 0.48 0.167" />
            </geometry>
        </collision>
    </link>
    <link name="omni_base_footprint" />
    <joint name="omni_base_footprint_joint" type="fixed">
        <origin rpy="0 0 0" xyz="0 0 0.0762" />
        <child link="omni_base_link" />
        <parent link="omni_base_footprint" />
    </joint>
    <!-- gazebo parameters are given here for base_link through base_footprint -->
    <!-- <gazebo reference="${base_name}_footprint">
      <kp>100000000.0</kp>
      <kd>10.0</kd>
      <mu1>0.1</mu1>
      <mu2>0.1</mu2>
      <fdir1>1 0 0</fdir1>
      <maxVel>10.0</maxVel>
      <minDepth>0.0005</minDepth>
      <laserRetro>0</laserRetro>
    </gazebo> -->
    <!-- IMU -->
    <!-- <xacro:imu_sensor name="${base_name}_imu" parent="${base_name}_link" update_rate="100.0">
      <origin xyz="-0.287 0 0.092163" rpy="0 0 ${90.0 * deg_to_rad}" />
    </xacro:imu_sensor> -->
    <!-- Docking link -->
    <link name="omni_base_dock_link">
        <inertial>
            <origin rpy="0 0 0" xyz="-0.0037082 1.5226E-18 -4.1633E-17" />
            <mass value="0.032242" />
            <inertia ixx="2.1302E-05" ixy="-1.0461E-21" ixz="6.6555E-22" iyy="1.2058E-05" iyz="-1.9453E-21" izz="1.0058E-05" />
        </inertial>
        <visual>
            <origin rpy="0 0 0" xyz="0 0 0" />
            <geometry>
                <mesh filename="package://omni_base_description/meshes/base/base_dock_link.stl" />
            </geometry>
            <material name="">
                <color rgba="0.25098 0.25098 0.25098 1" />
            </material>
        </visual>
        <collision>
            <origin rpy="0 0 0" xyz="0 0 0" />
            <geometry>
                <mesh filename="package://omni_base_description/meshes/base/base_dock_link.stl" />
            </geometry>
        </collision>
    </link>
    <joint name="omni_base_dock" type="fixed">
        <origin rpy="0 0 0" xyz="0.3535 0 0.0596" />
        <parent link="omni_base_link" />
        <child link="omni_base_dock_link" />
        <axis xyz="0 0 0" />
    </joint>
    <link name="omni_base_antenna_right_link">
        <inertial>
            <origin rpy="0 0 0" xyz="0.027807 -0.0085125 0.015138" />
            <mass value="0.02311" />
            <inertia ixx="2.3107E-06" ixy="5.0914e-06" ixz="8.5605E-08" iyy="1.7384E-05" iyz="-2.6206e-08" izz="1.8542E-05" />
        </inertial>
        <visual>
            <origin rpy="0 0 0" xyz="0 0 0" />
            <geometry>
                <mesh filename="package://omni_base_description/meshes/base/base_antena_link.stl" scale="1 1 1" />
            </geometry>
            <material name="">
                <color rgba="0.75294 0.75294 0.75294 1" />
            </material>
        </visual>
        <collision>
            <origin rpy="0 0 0" xyz="0 0 0" />
            <geometry>
                <mesh filename="package://omni_base_description/meshes/base/base_antena_link.stl" scale="1 1 1" />
            </geometry>
        </collision>
    </link>
    <joint name="omni_base_antenna_right_joint" type="fixed">
        <origin rpy="0 0 0" xyz="-0.2015 -0.13 0.2165" />
        <parent link="omni_base_link" />
        <child link="omni_base_antenna_right_link" />
        <axis xyz="0 0 0" />
    </joint>
    <gazebo reference="omni_base_antenna_right_link">
        <material>Gazebo/Black</material>
        <plugin name="gazebo_ros_control">
            <robotNamespace>/</robotNamespace>
        </plugin>
    </gazebo>
    <link name="omni_base_antenna_left_link">
        <inertial>
            <origin rpy="0 0 0" xyz="0.027807 0.0085125 0.015138" />
            <mass value="0.02311" />
            <inertia ixx="2.3107E-06" ixy="-5.0914e-06" ixz="8.5605E-08" iyy="1.7384E-05" iyz="2.6206e-08" izz="1.8542E-05" />
        </inertial>
        <visual>
            <origin rpy="0 0 0" xyz="0 0 0" />
            <geometry>
                <mesh filename="package://omni_base_description/meshes/base/base_antena_link.stl" scale="1 -1 1" />
            </geometry>
            <material name="">
                <color rgba="0.75294 0.75294 0.75294 1" />
            </material>
        </visual>
        <collision>
            <origin rpy="0 0 0" xyz="0 0 0" />
            <geometry>
                <mesh filename="package://omni_base_description/meshes/base/base_antena_link.stl" scale="1 -1 1" />
            </geometry>
        </collision>
    </link>
    <joint name="omni_base_antenna_left_joint" type="fixed">
        <origin rpy="0 0 0" xyz="-0.2015 0.13 0.2165" />
        <parent link="omni_base_link" />
        <child link="omni_base_antenna_left_link" />
        <axis xyz="0 0 0" />
    </joint>
    <gazebo reference="omni_base_antenna_left_link">
        <material>Gazebo/Black</material>
    </gazebo>
    <link name="suspension_front_right_link">
        <inertial>
            <origin rpy="0 0 0" xyz="-0.058182 -0.0043908 -0.0057695" />
            <mass value="1.2879" />
            <inertia ixx="0.0015947" ixy="-0.00013183" ixz="1.7315E-05" iyy="0.00060158" iyz="-6.0731e-05" izz="0.0015861" />
        </inertial>
        <visual>
            <origin rpy="0 0 0" xyz="0 0 0" />
            <geometry>
                <mesh filename="package://omni_base_description/meshes/wheels/suspension_front_link.stl" scale="1 1.0 1" />
            </geometry>
            <material name="">
                <color rgba="0.79216 0.81961 0.93333 1" />
            </material>
        </visual>
        <collision>
            <origin rpy="0 0 0" xyz="0 0 0" />
            <geometry>
                <mesh filename="package://omni_base_description/meshes/wheels/suspension_front_link.stl" scale="1 1.0 1" />
            </geometry>
        </collision>
        <kinematic>0</kinematic>
        <gravity>1</gravity>
    </link>
    <!-- Changed joint type to fixed joint. It is observed that the robot is loosing contact points due to some issues with the Gazebo Physics Engine. This makes the robot drift in localization when static due to added noise -->
    <joint name="suspension_front_right_joint" type="fixed">
        <origin rpy="0 0 -1.5707963267948966" xyz="0.244 -0.1725 0" />
        <parent link="omni_base_link" />
        <child link="suspension_front_right_link" />
        <axis xyz="0 0 1" />
    </joint>
    <link name="wheel_front_right_link">
        <inertial>
            <origin rpy="0 0 0" xyz="5.4922e-09 6.9775e-05 0.011144" />
            <mass value="0.70767" />
            <inertia ixx="0.00035492" ixy="7.5685e-13" ixz="3.8795E-11" iyy="0.00035529" iyz="-2.0284e-07" izz="0.00040131" />
        </inertial>
        <visual>
            <origin rpy="0 0 0" xyz="0 0 0" />
            <geometry>
                <mesh filename="package://omni_base_description/meshes/wheels/wheel_link.stl" scale="1 1 1.0" />
            </geometry>
            <material name="DarkGrey" />
        </visual>
        <collision>
            <origin rpy="0 0 0" xyz="0 0 0" />
            <geometry>
                <cylinder length="0.05" radius="0.0762" />
            </geometry>
        </collision>
    </link>
    <joint name="wheel_front_right_joint" type="continuous">
        <origin rpy="-1.5707963267948966 0 1.5707963267948966" xyz="0.050675 0 0" />
        <parent link="suspension_front_right_link" />
        <child link="wheel_front_right_link" />
        <axis xyz="0 0 1" />
        <limit effort="6.0" velocity="13.123359580052492" />
    </joint>
    <transmission name="wheel_front_right_trans">
        <type>transmission_interface/SimpleTransmission</type>
        <actuator name="wheel_front_right_motor">
            <mechanicalReduction>1.0</mechanicalReduction>
            <hardwareInterface>hardware_interface/EffortJointInterface</hardwareInterface>
        </actuator>
        <joint name="wheel_front_right_joint">
            <hardwareInterface>hardware_interface/VelocityJointInterface</hardwareInterface>
            <hardwareInterface>hardware_interface/JointStateInterface</hardwareInterface>
        </joint>
    </transmission>
    <!-- Gazebo extensions -->
    <!-- <xacro:wheel_gazebo side="${side}"/> -->
    <link name="suspension_front_left_link">
        <inertial>
            <origin rpy="0 0 0" xyz="-0.058182 0.0043908 -0.0057695" />
            <mass value="1.2879" />
            <inertia ixx="0.0015947" ixy="0.00013183" ixz="1.7315E-05" iyy="0.00060158" iyz="6.0731e-05" izz="0.0015861" />
        </inertial>
        <visual>
            <origin rpy="0 0 0" xyz="0 0 0" />
            <geometry>
                <mesh filename="package://omni_base_description/meshes/wheels/suspension_front_link.stl" scale="1 -1.0 1" />
            </geometry>
            <material name="">
                <color rgba="0.79216 0.81961 0.93333 1" />
            </material>
        </visual>
        <collision>
            <origin rpy="0 0 0" xyz="0 0 0" />
            <geometry>
                <mesh filename="package://omni_base_description/meshes/wheels/suspension_front_link.stl" scale="1 -1.0 1" />
            </geometry>
        </collision>
        <kinematic>0</kinematic>
        <gravity>1</gravity>
    </link>
    <!-- Changed joint type to fixed joint. It is observed that the robot is loosing contact points due to some issues with the Gazebo Physics Engine. This makes the robot drift in localization when static due to added noise -->
    <joint name="suspension_front_left_joint" type="fixed">
        <origin rpy="0 0 1.5707963267948966" xyz="0.244 0.1725 0" />
        <parent link="omni_base_link" />
        <child link="suspension_front_left_link" />
        <axis xyz="0 0 1" />
    </joint>
    <link name="wheel_front_left_link">
        <inertial>
            <origin rpy="0 0 0" xyz="5.4922e-09 -6.9775e-05 -0.011144" />
            <mass value="0.70767" />
            <inertia ixx="0.00035492" ixy="7.5685e-13" ixz="3.8795E-11" iyy="0.00035529" iyz="-2.0284e-07" izz="0.00040131" />
        </inertial>
        <visual>
            <origin rpy="0 0 0" xyz="0 0 0" />
            <geometry>
                <mesh filename="package://omni_base_description/meshes/wheels/wheel_link.stl" scale="1 1 -1.0" />
            </geometry>
            <material name="DarkGrey" />
        </visual>
        <collision>
            <origin rpy="0 0 0" xyz="0 0 0" />
            <geometry>
                <cylinder length="0.05" radius="0.0762" />
            </geometry>
        </collision>
    </link>
    <joint name="wheel_front_left_joint" type="continuous">
        <origin rpy="-1.5707963267948966 0 -1.5707963267948966" xyz="0.050675 0 0" />
        <parent link="suspension_front_left_link" />
        <child link="wheel_front_left_link" />
        <axis xyz="0 0 1" />
        <limit effort="6.0" velocity="13.123359580052492" />
    </joint>
    <transmission name="wheel_front_left_trans">
        <type>transmission_interface/SimpleTransmission</type>
        <actuator name="wheel_front_left_motor">
            <mechanicalReduction>1.0</mechanicalReduction>
            <hardwareInterface>hardware_interface/EffortJointInterface</hardwareInterface>
        </actuator>
        <joint name="wheel_front_left_joint">
            <hardwareInterface>hardware_interface/VelocityJointInterface</hardwareInterface>
            <hardwareInterface>hardware_interface/JointStateInterface</hardwareInterface>
        </joint>
    </transmission>
    <!-- Gazebo extensions -->
    <!-- <xacro:wheel_gazebo side="${side}"/> -->
    <link name="suspension_rear_right_link">
        <inertial>
            <origin rpy="0 0 0" xyz="-0.058182 0.0043908 -0.0057695" />
            <mass value="1.2879" />
            <inertia ixx="0.0015947" ixy="0.00013183" ixz="1.7315E-05" iyy="0.00060158" iyz="6.0731e-05" izz="0.0015861" />
        </inertial>
        <visual>
            <origin rpy="0 0 0" xyz="0 0 0" />
            <geometry>
                <mesh filename="package://omni_base_description/meshes/wheels/suspension_rear_link.stl" scale="1 1.0 1" />
            </geometry>
            <material name="">
                <color rgba="0.79216 0.81961 0.93333 1" />
            </material>
        </visual>
        <collision>
            <origin rpy="0 0 0" xyz="0 0 0" />
            <geometry>
                <mesh filename="package://omni_base_description/meshes/wheels/suspension_rear_link.stl" scale="1 1.0 1" />
            </geometry>
        </collision>
        <kinematic>0</kinematic>
        <gravity>1</gravity>
    </link>
    <!-- Changed joint type to fixed joint. It is observed that the robot is loosing contact points due to some issues with the Gazebo Physics Engine. This makes the robot drift in localization when static due to added noise -->
    <joint name="suspension_rear_right_joint" type="fixed">
        <origin rpy="0 0 -1.5707963267948966" xyz="-0.244 -0.1725 0" />
        <parent link="omni_base_link" />
        <child link="suspension_rear_right_link" />
        <axis xyz="0 0 1" />
    </joint>
    <link name="wheel_rear_right_link">
        <inertial>
            <origin rpy="0 0 0" xyz="-5.4922e-09 -6.9775e-05 0.011144" />
            <mass value="0.70767" />
            <inertia ixx="0.00035492" ixy="-7.5685e-13" ixz="3.8795E-11" iyy="0.00035529" iyz="2.0284e-07" izz="0.00040131" />
        </inertial>
        <visual>
            <origin rpy="0 0 0" xyz="0 0 0" />
            <geometry>
                <mesh filename="package://omni_base_description/meshes/wheels/wheel_link.stl" scale="1 1 1.0" />
            </geometry>
            <material name="DarkGrey" />
        </visual>
        <collision>
            <origin rpy="0 0 0" xyz="0 0 0" />
            <geometry>
                <cylinder length="0.05" radius="0.0762" />
            </geometry>
        </collision>
    </link>
    <joint name="wheel_rear_right_joint" type="continuous">
        <origin rpy="-1.5707963267948966 0 1.5707963267948966" xyz="0.050675 0 0" />
        <parent link="suspension_rear_right_link" />
        <child link="wheel_rear_right_link" />
        <axis xyz="0 0 1" />
        <limit effort="6.0" velocity="13.123359580052492" />
    </joint>
    <transmission name="wheel_rear_right_trans">
        <type>transmission_interface/SimpleTransmission</type>
        <actuator name="wheel_rear_right_motor">
            <mechanicalReduction>1.0</mechanicalReduction>
            <hardwareInterface>hardware_interface/EffortJointInterface</hardwareInterface>
        </actuator>
        <joint name="wheel_rear_right_joint">
            <hardwareInterface>hardware_interface/VelocityJointInterface</hardwareInterface>
            <hardwareInterface>hardware_interface/JointStateInterface</hardwareInterface>
        </joint>
    </transmission>
    <!-- Gazebo extensions -->
    <!-- <xacro:wheel_gazebo side="${side}"/> -->
    <link name="suspension_rear_left_link">
        <inertial>
            <origin rpy="0 0 0" xyz="-0.058182 -0.0043908 -0.0057695" />
            <mass value="1.2879" />
            <inertia ixx="0.0015947" ixy="-0.00013183" ixz="1.7315E-05" iyy="0.00060158" iyz="-6.0731e-05" izz="0.0015861" />
        </inertial>
        <visual>
            <origin rpy="0 0 0" xyz="0 0 0" />
            <geometry>
                <mesh filename="package://omni_base_description/meshes/wheels/suspension_rear_link.stl" scale="1 -1.0 1" />
            </geometry>
            <material name="">
                <color rgba="0.79216 0.81961 0.93333 1" />
            </material>
        </visual>
        <collision>
            <origin rpy="0 0 0" xyz="0 0 0" />
            <geometry>
                <mesh filename="package://omni_base_description/meshes/wheels/suspension_rear_link.stl" scale="1 -1.0 1" />
            </geometry>
        </collision>
        <kinematic>0</kinematic>
        <gravity>1</gravity>
    </link>
    <!-- Changed joint type to fixed joint. It is observed that the robot is loosing contact points due to some issues with the Gazebo Physics Engine. This makes the robot drift in localization when static due to added noise -->
    <joint name="suspension_rear_left_joint" type="fixed">
        <origin rpy="0 0 1.5707963267948966" xyz="-0.244 0.1725 0" />
        <parent link="omni_base_link" />
        <child link="suspension_rear_left_link" />
        <axis xyz="0 0 1" />
    </joint>
    <link name="wheel_rear_left_link">
        <inertial>
            <origin rpy="0 0 0" xyz="-5.4922e-09 6.9775e-05 -0.011144" />
            <mass value="0.70767" />
            <inertia ixx="0.00035492" ixy="-7.5685e-13" ixz="3.8795E-11" iyy="0.00035529" iyz="2.0284e-07" izz="0.00040131" />
        </inertial>
        <visual>
            <origin rpy="0 0 0" xyz="0 0 0" />
            <geometry>
                <mesh filename="package://omni_base_description/meshes/wheels/wheel_link.stl" scale="1 1 -1.0" />
            </geometry>
            <material name="DarkGrey" />
        </visual>
        <collision>
            <origin rpy="0 0 0" xyz="0 0 0" />
            <geometry>
                <cylinder length="0.05" radius="0.0762" />
            </geometry>
        </collision>
    </link>
    <joint name="wheel_rear_left_joint" type="continuous">
        <origin rpy="-1.5707963267948966 0 -1.5707963267948966" xyz="0.050675 0 0" />
        <parent link="suspension_rear_left_link" />
        <child link="wheel_rear_left_link" />
        <axis xyz="0 0 1" />
        <limit effort="6.0" velocity="13.123359580052492" />
    </joint>
    <transmission name="wheel_rear_left_trans">
        <type>transmission_interface/SimpleTransmission</type>
        <actuator name="wheel_rear_left_motor">
            <mechanicalReduction>1.0</mechanicalReduction>
            <hardwareInterface>hardware_interface/EffortJointInterface</hardwareInterface>
        </actuator>
        <joint name="wheel_rear_left_joint">
            <hardwareInterface>hardware_interface/VelocityJointInterface</hardwareInterface>
            <hardwareInterface>hardware_interface/JointStateInterface</hardwareInterface>
        </joint>
    </transmission>
    <!-- Gazebo extensions -->
    <!-- <xacro:wheel_gazebo side="${side}"/> -->
    <!-- Links and Joints for Base 3DOF Translation-->
    <link name="x_base" />
    <joint name="translate_x" type="prismatic">
        <origin rpy="0.0 0.0 0.0" xyz="0.0 0.0 0.0" />
        <parent link="world" />
        <child link="x_base" />
        <axis xyz="1.0 0.0 0.0" />
        <limit effort="0.0" lower="-3.0" upper="3.0" velocity="0.0" />
    </joint>
    <link name="y_base" />
    <joint name="translate_y" type="prismatic">
        <origin rpy="0.0 0.0 0.0" xyz="0.0 0.0 0.0" />
        <parent link="x_base" />
        <child link="y_base" />
        <axis xyz="0.0 1.0 0.0" />
        <limit effort="0.0" lower="-3.0" upper="3.0" velocity="0.0" />
    </joint>
    <link name="z_base" />
    <joint name="rotate_z" type="revolute">
        <origin rpy="0.0 0.0 0.0" xyz="0.0 0.0 0.0" />
        <parent link="y_base" />
        <child link="z_base" />
        <axis xyz="0.0 0.0 1.0" />
        <limit effort="0.0" lower="-3.1415" upper="10.0" velocity="0.0" />
    </joint>
    <joint name="affix" type="fixed">
        <origin rpy="0.0 0.0 0.0" xyz="0.0 0.0 0.0" />
        <parent link="z_base" />
        <child link="omni_base_footprint" />
    </joint>
    <!-- Base to Kinova Mounting-->
    <link name="base_bot_mount">
        <visual>
            <origin rpy="0 0 0" xyz="0 0 0" />
            <geometry>
                <mesh filename="package://kinova_gen3_description/meshes/base_bot_platform.stl" scale="1 1 1" />
            </geometry>
            <material name="">
                <color rgba="0.1 0.1 0.1 1" />
            </material>
        </visual>
        <collision>
            <origin rpy="0 0 0" xyz="0 0 0" />
            <geometry>
                <mesh filename="package://kinova_gen3_description/meshes/base_bot_platform.stl" scale="1 1 1" />
            </geometry>
        </collision>
        <inertial>
            <mass value="0.1" />
            <origin xyz="0 0 0" rpy="0 0 0" />
            <inertia ixx="0.03" iyy="0.03" izz="0.03" ixy="0.0" ixz="0.0" iyz="0.0" />
        </inertial>
    </link>
    <joint name="base_mount" type="fixed">
        <origin rpy="0.0 0.0 0.0" xyz="0.0 0.0 0.225" />
        <parent link="omni_base_link" />
        <child link="base_bot_mount" />
    </joint>
    <joint name="mount_bot" type="fixed">
        <origin rpy="0.0 0.0 0.0" xyz="0.0 0.0 0.01" />
        <parent link="base_bot_mount" />
        <child link="kinova_base_link" />
    </joint>
    <link name="kinova_base_link">
        <inertial>
            <origin rpy="0 0 0" xyz="-0.000648 -0.000166 0.084487" />
            <mass value="1.697" />
            <inertia ixx="0.004622" ixy="9E-06" ixz="6E-05" iyy="0.004495" iyz="9E-06" izz="0.002079" />
        </inertial>
        <visual>
            <origin rpy="0 0 0" xyz="0 0 0" />
            <geometry>
                <mesh filename="package://kinova_gen3_description/meshes/base_link.STL" />
            </geometry>
            <material name="">
                <color rgba="0.75294 0.75294 0.75294 1" />
            </material>
        </visual>
        <collision>
            <origin rpy="0 0 0" xyz="0 0 0" />
            <geometry>
                <mesh filename="package://kinova_gen3_description/meshes/base_link.STL" />
            </geometry>
        </collision>
    </link>
    <link name="kinova_shoulder_link">
        <inertial>
            <origin rpy="0 0 0" xyz="-2.3E-05 -0.010364 -0.07336" />
            <mass value="1.3773" />
            <inertia ixx="0.00457" ixy="1E-06" ixz="2E-06" iyy="0.004831" iyz="0.000448" izz="0.001409" />
        </inertial>
        <visual>
            <origin rpy="0 0 0" xyz="0 0 0" />
            <geometry>
                <mesh filename="package://kinova_gen3_description/meshes/shoulder_link.STL" />
            </geometry>
            <material name="">
                <color rgba="0.75294 0.75294 0.75294 1" />
            </material>
        </visual>
        <collision>
            <origin rpy="0 0 0" xyz="0 0 0" />
            <geometry>
                <mesh filename="package://kinova_gen3_description/meshes/shoulder_link.STL" />
            </geometry>
        </collision>
    </link>
    <joint name="kinova_joint_1" type="continuous">
        <origin rpy="3.1416 2.7629E-18 -4.9305E-36" xyz="0 0 0.15643" />
        <parent link="kinova_base_link" />
        <child link="kinova_shoulder_link" />
        <axis xyz="0 0 1" />
        <limit effort="39" velocity="1.3963" />
    </joint>
    <link name="kinova_half_arm_1_link">
        <inertial>
            <origin rpy="0 0 0" xyz="-4.4E-05 -0.09958 -0.013278" />
            <mass value="1.1636" />
            <inertia ixx="0.011088" ixy="5E-06" ixz="0" iyy="0.001072" iyz="-0.000691" izz="0.011255" />
        </inertial>
        <visual>
            <origin rpy="0 0 0" xyz="0 0 0" />
            <geometry>
                <mesh filename="package://kinova_gen3_description/meshes/half_arm_1_link.STL" />
            </geometry>
            <material name="">
                <color rgba="0.75294 0.75294 0.75294 1" />
            </material>
        </visual>
        <collision>
            <origin rpy="0 0 0" xyz="0 0 0" />
            <geometry>
                <mesh filename="package://kinova_gen3_description/meshes/half_arm_1_link.STL" />
            </geometry>
        </collision>
    </link>
    <joint name="kinova_joint_2" type="revolute">
        <origin rpy="1.5708 2.1343E-17 -1.1102E-16" xyz="0 0.005375 -0.12838" />
        <parent link="kinova_shoulder_link" />
        <child link="kinova_half_arm_1_link" />
        <axis xyz="0 0 1" />
        <limit effort="39" lower="-2.24" upper="2.24" velocity="1.3963" />
    </joint>
    <link name="kinova_half_arm_2_link">
        <inertial>
            <origin rpy="0 0 0" xyz="-4.4E-05 -0.006641 -0.117892" />
            <mass value="1.1636" />
            <inertia ixx="0.010932" ixy="0" ixz="-7E-06" iyy="0.011127" iyz="0.000606" izz="0.001043" />
        </inertial>
        <visual>
            <origin rpy="0 0 0" xyz="0 0 0" />
            <geometry>
                <mesh filename="package://kinova_gen3_description/meshes/half_arm_2_link.STL" />
            </geometry>
            <material name="">
                <color rgba="0.75294 0.75294 0.75294 1" />
            </material>
        </visual>
        <collision>
            <origin rpy="0 0 0" xyz="0 0 0" />
            <geometry>
                <mesh filename="package://kinova_gen3_description/meshes/half_arm_2_link.STL" />
            </geometry>
        </collision>
    </link>
    <joint name="kinova_joint_3" type="continuous">
        <origin rpy="-1.5708 1.2326E-32 -2.9122E-16" xyz="0 -0.21038 -0.006375" />
        <parent link="kinova_half_arm_1_link" />
        <child link="kinova_half_arm_2_link" />
        <axis xyz="0 0 1" />
        <limit effort="39" velocity="1.3963" />
    </joint>
    <link name="kinova_forearm_link">
        <inertial>
            <origin rpy="0 0 0" xyz="-1.8E-05 -0.075478 -0.015006" />
            <mass value="0.9302" />
            <inertia ixx="0.008147" ixy="-1E-06" ixz="0" iyy="0.000631" iyz="-0.0005" izz="0.008316" />
        </inertial>
        <visual>
            <origin rpy="0 0 0" xyz="0 0 0" />
            <geometry>
                <mesh filename="package://kinova_gen3_description/meshes/forearm_link.STL" />
            </geometry>
            <material name="">
                <color rgba="0.75294 0.75294 0.75294 1" />
            </material>
        </visual>
        <collision>
            <origin rpy="0 0 0" xyz="0 0 0" />
            <geometry>
                <mesh filename="package://kinova_gen3_description/meshes/forearm_link.STL" />
            </geometry>
        </collision>
    </link>
    <joint name="kinova_joint_4" type="revolute">
        <origin rpy="1.5708 -6.6954E-17 -1.6653E-16" xyz="0 0.006375 -0.21038" />
        <parent link="kinova_half_arm_2_link" />
        <child link="kinova_forearm_link" />
        <axis xyz="0 0 1" />
        <limit effort="39" lower="-2.57" upper="2.57" velocity="1.3963" />
    </joint>
    <link name="kinova_spherical_wrist_1_link">
        <inertial>
            <origin rpy="0 0 0" xyz="1E-06 -0.009432 -0.063883" />
            <mass value="0.6781" />
            <inertia ixx="0.001596" ixy="0" ixz="0" iyy="0.001607" iyz="0.000256" izz="0.000399" />
        </inertial>
        <visual>
            <origin rpy="0 0 0" xyz="0 0 0" />
            <geometry>
                <mesh filename="package://kinova_gen3_description/meshes/spherical_wrist_1_link.STL" />
            </geometry>
            <material name="">
                <color rgba="0.75294 0.75294 0.75294 1" />
            </material>
        </visual>
        <collision>
            <origin rpy="0 0 0" xyz="0 0 0" />
            <geometry>
                <mesh filename="package://kinova_gen3_description/meshes/spherical_wrist_1_link.STL" />
            </geometry>
        </collision>
    </link>
    <joint name="kinova_joint_5" type="continuous">
        <origin rpy="-1.5708 2.2204E-16 -6.373E-17" xyz="0 -0.20843 -0.006375" />
        <parent link="kinova_forearm_link" />
        <child link="kinova_spherical_wrist_1_link" />
        <axis xyz="0 0 1" />
        <limit effort="9" velocity="1.2218" />
    </joint>
    <link name="kinova_spherical_wrist_2_link">
        <inertial>
            <origin rpy="0 0 0" xyz="1E-06 -0.045483 -0.00965" />
            <mass value="0.6781" />
            <inertia ixx="0.001641" ixy="0" ixz="0" iyy="0.00041" iyz="-0.000278" izz="0.001641" />
        </inertial>
        <visual>
            <origin rpy="0 0 0" xyz="0 0 0" />
            <geometry>
                <mesh filename="package://kinova_gen3_description/meshes/spherical_wrist_2_link.STL" />
            </geometry>
            <material name="">
                <color rgba="0.75294 0.75294 0.75294 1" />
            </material>
        </visual>
        <collision>
            <origin rpy="0 0 0" xyz="0 0 0" />
            <geometry>
                <mesh filename="package://kinova_gen3_description/meshes/spherical_wrist_2_link.STL" />
            </geometry>
        </collision>
    </link>
    <joint name="kinova_joint_6" type="revolute">
        <origin rpy="1.5708 9.2076E-28 -8.2157E-15" xyz="0 0.00017505 -0.10593" />
        <parent link="kinova_spherical_wrist_1_link" />
        <child link="kinova_spherical_wrist_2_link" />
        <axis xyz="0 0 1" />
        <limit effort="9" lower="-2.09" upper="2.09" velocity="1.2218" />
    </joint>
    <link name="kinova_bracelet_link">
        <inertial>
            <origin rpy="0 0 0" xyz="-9.3E-05 0.000132 -0.022905" />
            <mass value="0.364" />
            <inertia ixx="0.000214" ixy="0" ixz="1E-06" iyy="0.000223" iyz="-2E-06" izz="0.00024" />
        </inertial>
        <visual>
            <origin rpy="0 0 0" xyz="0 0 0" />
            <geometry>
                <mesh filename="package://kinova_gen3_description/meshes/bracelet_no_vision_link.STL" />
            </geometry>
            <material name="">
                <color rgba="0.75294 0.75294 0.75294 1" />
            </material>
        </visual>
        <collision>
            <origin rpy="0 0 0" xyz="0 0 0" />
            <geometry>
                <mesh filename="package://kinova_gen3_description/meshes/bracelet_no_vision_link.STL" />
            </geometry>
        </collision>
    </link>
    <joint name="kinova_joint_7" type="continuous">
        <origin rpy="-1.5708 -5.5511E-17 9.6396E-17" xyz="0 -0.10593 -0.00017505" />
        <parent link="kinova_spherical_wrist_2_link" />
        <child link="kinova_bracelet_link" />
        <axis xyz="0 0 1" />
        <limit effort="9" velocity="1.2218" />
    </joint>
    <link name="kinova_end_effector_link" />
    <joint name="kinova_end_effector" type="fixed">
        <origin rpy="3.14159265358979 1.09937075168372E-32 0" xyz="0 0 -0.0615250000000001" />
        <parent link="kinova_bracelet_link" />
        <child link="kinova_end_effector_link" />
        <axis xyz="0 0 0" />
    </joint>
    <!-- Bot to Gripper Joint -->
    <joint name="bot_gripper" type="fixed">
        <origin rpy="0.0 0.0 0.0" xyz="0.0 0.0 0.0" />
        <parent link="kinova_end_effector_link" />
        <child link="robotiq_arg2f_base_link" />
    </joint>
    <link name="robotiq_arg2f_base_link">
        <inertial>
            <origin rpy="0 0 0" xyz="8.625E-08 -4.6583E-06 0.03145" />
            <mass value="0.22652" />
            <inertia ixx="0.00020005" ixy="-4.2442E-10" ixz="-2.9069E-10" iyy="0.00017832" iyz="-3.4402E-08" izz="0.00013478" />
        </inertial>
        <visual>
            <origin rpy="0 0 0" xyz="0 0 0" />
            <geometry>
                <mesh filename="package://robotiq_2f_85_gripper_description/meshes/visual/robotiq_arg2f_85_base_link.dae" scale="0.001 0.001 0.001" />
            </geometry>
            <material name="">
                <color rgba="0.1 0.1 0.1 1" />
            </material>
        </visual>
        <collision>
            <origin rpy="0 0 0" xyz="0 0 0" />
            <geometry>
                <mesh filename="package://robotiq_2f_85_gripper_description/meshes/collision/robotiq_arg2f_base_link.stl" />
            </geometry>
        </collision>
    </link>
    <link name="left_outer_knuckle">
        <!--<inertial>
        <origin xyz="-0.000200000000003065 0.0199435877845359 0.0292245259211331" rpy="0 0 0" />
        <mass value="0.00853198276973456" />
        <inertia ixx="2.89328108496468E-06" ixy="-1.57935047237397E-19" ixz="-1.93980378593255E-19" iyy="1.86719750325683E-06" iyz="-1.21858577871576E-06" izz="1.21905238907251E-06" />
        </inertial> -->
        <visual>
            <origin rpy="0 0 0" xyz="0 0 0" />
            <geometry>
                <mesh filename="package://robotiq_2f_85_gripper_description/meshes/visual/robotiq_arg2f_85_outer_knuckle.dae" scale="0.001 0.001 0.001" />
            </geometry>
            <material name="">
                <color rgba="0.792156862745098 0.819607843137255 0.933333333333333 1" />
            </material>
        </visual>
        <collision>
            <origin rpy="0 0 0" xyz="0 0 0" />
            <geometry>
                <mesh filename="package://robotiq_2f_85_gripper_description/meshes/collision/robotiq_arg2f_85_outer_knuckle.dae" scale="0.001 0.001 0.001" />
            </geometry>
        </collision>
        <inertial>
            <mass value="0.1" />
            <origin xyz="0 0 0" rpy="0 0 0" />
            <inertia ixx="0.03" iyy="0.03" izz="0.03" ixy="0.0" ixz="0.0" iyz="0.0" />
        </inertial>
    </link>
    <link name="left_outer_finger">
        <!--<inertial>
        <origin xyz="0.00030115855001899 0.0373907951953854 -0.0208027427000385" rpy="0 0 0" />
        <mass value="0.022614240507152" />
        <inertia ixx="1.52518312458174E-05" ixy="9.76583423954399E-10" ixz="-5.43838577022588E-10" iyy="6.17694243867776E-06" iyz="6.78636130740228E-06" izz="1.16494917907219E-05" />
        </inertial> -->
        <visual>
            <origin rpy="0 0 0" xyz="0 0 0" />
            <geometry>
                <mesh filename="package://robotiq_2f_85_gripper_description/meshes/visual/robotiq_arg2f_85_outer_finger.dae" scale="0.001 0.001 0.001" />
            </geometry>
            <material name="">
                <color rgba="0.1 0.1 0.1 1" />
            </material>
        </visual>
        <collision>
            <origin rpy="0 0 0" xyz="0 0 0" />
            <geometry>
                <mesh filename="package://robotiq_2f_85_gripper_description/meshes/collision/robotiq_arg2f_85_outer_finger.dae" scale="0.001 0.001 0.001" />
            </geometry>
        </collision>
        <inertial>
            <mass value="0.1" />
            <origin xyz="0 0 0" rpy="0 0 0" />
            <inertia ixx="0.03" iyy="0.03" izz="0.03" ixy="0.0" ixz="0.0" iyz="0.0" />
        </inertial>
    </link>
    <link name="left_inner_finger">
        <!--<inertial>
        <origin xyz="0.000299999999999317 0.0160078233491243 -0.0136945669206257" rpy="0 0 0" />
        <mass value="0.0104003125914103" />
        <inertia ixx="2.71909453810972E-06" ixy="1.35402465472579E-21" ixz="-7.1817349065269E-22" iyy="7.69100314106116E-07" iyz="6.74715432769696E-07" izz="2.30315190420171E-06" />
        </inertial> -->
        <visual>
            <origin rpy="0 0 0" xyz="0 0 0" />
            <geometry>
                <mesh filename="package://robotiq_2f_85_gripper_description/meshes/visual/robotiq_arg2f_85_inner_finger.dae" scale="0.001 0.001 0.001" />
            </geometry>
            <material name="">
                <color rgba="0.1 0.1 0.1 1" />
            </material>
        </visual>
        <collision>
            <origin rpy="0 0 0" xyz="0 0 0" />
            <geometry>
                <mesh filename="package://robotiq_2f_85_gripper_description/meshes/collision/robotiq_arg2f_85_inner_finger.dae" scale="0.001 0.001 0.001" />
            </geometry>
        </collision>
        <inertial>
            <mass value="0.1" />
            <origin xyz="0 0 0" rpy="0 0 0" />
            <inertia ixx="0.03" iyy="0.03" izz="0.03" ixy="0.0" ixz="0.0" iyz="0.0" />
        </inertial>
    </link>
    <link name="left_inner_finger_pad">
        <visual>
            <origin rpy="0 0 0" xyz="0 0 0" />
            <geometry>
                <box size="0.022 0.00635 0.0375" />
            </geometry>
            <material name="">
                <color rgba="0.9 0.9 0.9 1" />
            </material>
        </visual>
        <collision>
            <origin rpy="0 0 0" xyz="0 0 0" />
            <geometry>
                <box size="0.022 0.00635 0.0375" />
            </geometry>
            <material name="">
                <color rgba="0.9 0.0 0.0 1" />
            </material>
        </collision>
        <inertial>
            <mass value="0.1" />
            <origin xyz="0 0 0" rpy="0 0 0" />
            <inertia ixx="0.03" iyy="0.03" izz="0.03" ixy="0.0" ixz="0.0" iyz="0.0" />
        </inertial>
    </link>
    <link name="left_inner_knuckle">
        <!--<inertial>
        <origin xyz="0.000123011831763771 0.0507850843201817 0.00103968640075166" rpy="0 0 0" />
       <mass value="0.0271177346495152" />
        <inertia ixx="2.61910379223783E-05" ixy="-2.43616858946494E-07" ixz="-6.37789906117123E-09" iyy="2.8270243746167E-06" iyz="-5.37200748039765E-07" izz="2.83695868220296E-05" />
        </inertial> -->
        <visual>
            <origin rpy="0 0 0" xyz="0 0 0" />
            <geometry>
                <mesh filename="package://robotiq_2f_85_gripper_description/meshes/visual/robotiq_arg2f_85_inner_knuckle.dae" scale="0.001 0.001 0.001" />
            </geometry>
            <material name="">
                <color rgba="0.1 0.1 0.1 1" />
            </material>
        </visual>
        <collision>
            <origin rpy="0 0 0" xyz="0 0 0" />
            <geometry>
                <mesh filename="package://robotiq_2f_85_gripper_description/meshes/collision/robotiq_arg2f_85_inner_knuckle.dae" scale="0.001 0.001 0.001" />
            </geometry>
        </collision>
        <inertial>
            <mass value="0.1" />
            <origin xyz="0 0 0" rpy="0 0 0" />
            <inertia ixx="0.03" iyy="0.03" izz="0.03" ixy="0.0" ixz="0.0" iyz="0.0" />
        </inertial>
    </link>
    <link name="right_outer_knuckle">
        <!--<inertial>
        <origin xyz="-0.000200000000003065 0.0199435877845359 0.0292245259211331" rpy="0 0 0" />
        <mass value="0.00853198276973456" />
        <inertia ixx="2.89328108496468E-06" ixy="-1.57935047237397E-19" ixz="-1.93980378593255E-19" iyy="1.86719750325683E-06" iyz="-1.21858577871576E-06" izz="1.21905238907251E-06" />
        </inertial> -->
        <visual>
            <origin rpy="0 0 0" xyz="0 0 0" />
            <geometry>
                <mesh filename="package://robotiq_2f_85_gripper_description/meshes/visual/robotiq_arg2f_85_outer_knuckle.dae" scale="0.001 0.001 0.001" />
            </geometry>
            <material name="">
                <color rgba="0.792156862745098 0.819607843137255 0.933333333333333 1" />
            </material>
        </visual>
        <collision>
            <origin rpy="0 0 0" xyz="0 0 0" />
            <geometry>
                <mesh filename="package://robotiq_2f_85_gripper_description/meshes/collision/robotiq_arg2f_85_outer_knuckle.dae" scale="0.001 0.001 0.001" />
            </geometry>
        </collision>
        <inertial>
            <mass value="0.1" />
            <origin xyz="0 0 0" rpy="0 0 0" />
            <inertia ixx="0.03" iyy="0.03" izz="0.03" ixy="0.0" ixz="0.0" iyz="0.0" />
        </inertial>
    </link>
    <link name="right_outer_finger">
        <!--<inertial>
        <origin xyz="0.00030115855001899 0.0373907951953854 -0.0208027427000385" rpy="0 0 0" />
        <mass value="0.022614240507152" />
        <inertia ixx="1.52518312458174E-05" ixy="9.76583423954399E-10" ixz="-5.43838577022588E-10" iyy="6.17694243867776E-06" iyz="6.78636130740228E-06" izz="1.16494917907219E-05" />
        </inertial> -->
        <visual>
            <origin rpy="0 0 0" xyz="0 0 0" />
            <geometry>
                <mesh filename="package://robotiq_2f_85_gripper_description/meshes/visual/robotiq_arg2f_85_outer_finger.dae" scale="0.001 0.001 0.001" />
            </geometry>
            <material name="">
                <color rgba="0.1 0.1 0.1 1" />
            </material>
        </visual>
        <collision>
            <origin rpy="0 0 0" xyz="0 0 0" />
            <geometry>
                <mesh filename="package://robotiq_2f_85_gripper_description/meshes/collision/robotiq_arg2f_85_outer_finger.dae" scale="0.001 0.001 0.001" />
            </geometry>
        </collision>
        <inertial>
            <mass value="0.1" />
            <origin xyz="0 0 0" rpy="0 0 0" />
            <inertia ixx="0.03" iyy="0.03" izz="0.03" ixy="0.0" ixz="0.0" iyz="0.0" />
        </inertial>
    </link>
    <link name="right_inner_finger">
        <!--<inertial>
        <origin xyz="0.000299999999999317 0.0160078233491243 -0.0136945669206257" rpy="0 0 0" />
        <mass value="0.0104003125914103" />
        <inertia ixx="2.71909453810972E-06" ixy="1.35402465472579E-21" ixz="-7.1817349065269E-22" iyy="7.69100314106116E-07" iyz="6.74715432769696E-07" izz="2.30315190420171E-06" />
        </inertial> -->
        <visual>
            <origin rpy="0 0 0" xyz="0 0 0" />
            <geometry>
                <mesh filename="package://robotiq_2f_85_gripper_description/meshes/visual/robotiq_arg2f_85_inner_finger.dae" scale="0.001 0.001 0.001" />
            </geometry>
            <material name="">
                <color rgba="0.1 0.1 0.1 1" />
            </material>
        </visual>
        <collision>
            <origin rpy="0 0 0" xyz="0 0 0" />
            <geometry>
                <mesh filename="package://robotiq_2f_85_gripper_description/meshes/collision/robotiq_arg2f_85_inner_finger.dae" scale="0.001 0.001 0.001" />
            </geometry>
        </collision>
        <inertial>
            <mass value="0.1" />
            <origin xyz="0 0 0" rpy="0 0 0" />
            <inertia ixx="0.03" iyy="0.03" izz="0.03" ixy="0.0" ixz="0.0" iyz="0.0" />
        </inertial>
    </link>
    <link name="right_inner_finger_pad">
        <visual>
            <origin rpy="0 0 0" xyz="0 0 0" />
            <geometry>
                <box size="0.022 0.00635 0.0375" />
            </geometry>
            <material name="">
                <color rgba="0.9 0.9 0.9 1" />
            </material>
        </visual>
        <collision>
            <origin rpy="0 0 0" xyz="0 0 0" />
            <geometry>
                <box size="0.022 0.00635 0.0375" />
            </geometry>
            <material name="">
                <color rgba="0.9 0.0 0.0 1" />
            </material>
        </collision>
        <inertial>
            <mass value="0.1" />
            <origin xyz="0 0 0" rpy="0 0 0" />
            <inertia ixx="0.03" iyy="0.03" izz="0.03" ixy="0.0" ixz="0.0" iyz="0.0" />
        </inertial>
    </link>
    <link name="right_inner_knuckle">
        <!--<inertial>
        <origin xyz="0.000123011831763771 0.0507850843201817 0.00103968640075166" rpy="0 0 0" />
       <mass value="0.0271177346495152" />
        <inertia ixx="2.61910379223783E-05" ixy="-2.43616858946494E-07" ixz="-6.37789906117123E-09" iyy="2.8270243746167E-06" iyz="-5.37200748039765E-07" izz="2.83695868220296E-05" />
        </inertial> -->
        <visual>
            <origin rpy="0 0 0" xyz="0 0 0" />
            <geometry>
                <mesh filename="package://robotiq_2f_85_gripper_description/meshes/visual/robotiq_arg2f_85_inner_knuckle.dae" scale="0.001 0.001 0.001" />
            </geometry>
            <material name="">
                <color rgba="0.1 0.1 0.1 1" />
            </material>
        </visual>
        <collision>
            <origin rpy="0 0 0" xyz="0 0 0" />
            <geometry>
                <mesh filename="package://robotiq_2f_85_gripper_description/meshes/collision/robotiq_arg2f_85_inner_knuckle.dae" scale="0.001 0.001 0.001" />
            </geometry>
        </collision>
        <inertial>
            <mass value="0.1" />
            <origin xyz="0 0 0" rpy="0 0 0" />
            <inertia ixx="0.03" iyy="0.03" izz="0.03" ixy="0.0" ixz="0.0" iyz="0.0" />
        </inertial>
    </link>
    <joint name="finger_joint" type="revolute">
        <origin rpy="0 0 3.141592653589793" xyz="0 -0.0306011 0.054904" />
        <parent link="robotiq_arg2f_base_link" />
        <child link="left_outer_knuckle" />
        <axis xyz="1 0 0" />
        <limit effort="1000" lower="0" upper="0.8" velocity="2.0" />
    </joint>
    <joint name="left_outer_finger_joint" type="fixed">
        <origin rpy="0 0 0" xyz="0 0.0315 -0.0041" />
        <parent link="left_outer_knuckle" />
        <child link="left_outer_finger" />
        <axis xyz="1 0 0" />
    </joint>
    <joint name="left_inner_knuckle_joint" type="revolute">
        <!-- <origin xyz="0 ${reflect * -0.0127} 0.06142" rpy="${pi / 2 + .725} 0 ${(reflect - 1) * pi / 2}" /> -->
        <origin rpy="0 0 3.141592653589793" xyz="0 -0.0127 0.06142" />
        <parent link="robotiq_arg2f_base_link" />
        <child link="left_inner_knuckle" />
        <axis xyz="1 0 0" />
        <limit effort="1000" lower="0" upper="0.8757" velocity="2.0" />
        <mimic joint="finger_joint" multiplier="1" offset="0" />
    </joint>
    <joint name="left_inner_finger_joint" type="revolute">
        <origin rpy="0 0 0" xyz="0 0.0061 0.0471" />
        <parent link="left_outer_finger" />
        <child link="left_inner_finger" />
        <axis xyz="1 0 0" />
        <limit effort="1000" lower="-0.8757" upper="0" velocity="2.0" />
        <mimic joint="finger_joint" multiplier="-1" offset="0" />
    </joint>
    <joint name="left_inner_finger_pad_joint" type="fixed">
        <origin rpy="0 0 0" xyz="0 -0.0220203446692936 0.03242" />
        <parent link="left_inner_finger" />
        <child link="left_inner_finger_pad" />
        <axis xyz="0 0 1" />
    </joint>
    <joint name="right_outer_knuckle_joint" type="revolute">
        <origin rpy="0 0 0" xyz="0 0.0306011 0.054904" />
        <parent link="robotiq_arg2f_base_link" />
        <child link="right_outer_knuckle" />
        <axis xyz="1 0 0" />
        <limit effort="1000" lower="0" upper="0.81" velocity="2.0" />
        <mimic joint="finger_joint" multiplier="1" offset="0" />
    </joint>
    <joint name="right_outer_finger_joint" type="fixed">
        <origin rpy="0 0 0" xyz="0 0.0315 -0.0041" />
        <parent link="right_outer_knuckle" />
        <child link="right_outer_finger" />
        <axis xyz="1 0 0" />
    </joint>
    <joint name="right_inner_knuckle_joint" type="revolute">
        <!-- <origin xyz="0 ${reflect * -0.0127} 0.06142" rpy="${pi / 2 + .725} 0 ${(reflect - 1) * pi / 2}" /> -->
        <origin rpy="0 0 0.0" xyz="0 0.0127 0.06142" />
        <parent link="robotiq_arg2f_base_link" />
        <child link="right_inner_knuckle" />
        <axis xyz="1 0 0" />
        <limit effort="1000" lower="0" upper="0.8757" velocity="2.0" />
        <mimic joint="finger_joint" multiplier="1" offset="0" />
    </joint>
    <joint name="right_inner_finger_joint" type="revolute">
        <origin rpy="0 0 0" xyz="0 0.0061 0.0471" />
        <parent link="right_outer_finger" />
        <child link="right_inner_finger" />
        <axis xyz="1 0 0" />
        <limit effort="1000" lower="-0.8757" upper="0" velocity="2.0" />
        <mimic joint="finger_joint" multiplier="-1" offset="0" />
    </joint>
    <joint name="right_inner_finger_pad_joint" type="fixed">
        <origin rpy="0 0 0" xyz="0 -0.0220203446692936 0.03242" />
        <parent link="right_inner_finger" />
        <child link="right_inner_finger_pad" />
        <axis xyz="0 0 1" />
    </joint>
    <transmission name="finger_joint_trans">
        <type>transmission_interface/SimpleTransmission</type>
        <joint name="finger_joint">
            <hardwareInterface>PositionJointInterface</hardwareInterface>
        </joint>
        <actuator name="finger_joint_motor">
            <mechanicalReduction>1</mechanicalReduction>
            <hardwareInterface>hardware_interface/EffortJointInterface</hardwareInterface>
        </actuator>
    </transmission>
    <transmission name="trans_translate_x">
        <type>transmission_interface/SimpleTransmission</type>
        <joint name="translate_x">
            <hardwareInterface>hardware_interface/PositionJointInterface</hardwareInterface>
        </joint>
        <actuator name="translate_x_motor">
            <hardwareInterface>hardware_interface/PositionJointInterface</hardwareInterface>
            <mechanicalReduction>1</mechanicalReduction>
        </actuator>
    </transmission>
    <transmission name="trans_translate_y">
        <type>transmission_interface/SimpleTransmission</type>
        <joint name="translate_y">
            <hardwareInterface>hardware_interface/EffortJointInterface</hardwareInterface>
        </joint>
        <actuator name="translate_y_motor">
            <hardwareInterface>hardware_interface/EffortJointInterface</hardwareInterface>
            <mechanicalReduction>1</mechanicalReduction>
        </actuator>
    </transmission>
    <transmission name="trans_rotate_z">
        <type>transmission_interface/SimpleTransmission</type>
        <joint name="rotate_z">
            <hardwareInterface>hardware_interface/EffortJointInterface</hardwareInterface>
        </joint>
        <actuator name="rotate_z_motor">
            <hardwareInterface>hardware_interface/EffortJointInterface</hardwareInterface>
            <mechanicalReduction>1</mechanicalReduction>
        </actuator>
    </transmission>
    <transmission name="trans_kinova_joint_1">
        <type>transmission_interface/SimpleTransmission</type>
        <joint name="kinova_joint_1">
            <hardwareInterface>hardware_interface/EffortJointInterface</hardwareInterface>
        </joint>
        <actuator name="kinova_joint_1_motor">
            <hardwareInterface>hardware_interface/EffortJointInterface</hardwareInterface>
            <mechanicalReduction>1</mechanicalReduction>
        </actuator>
    </transmission>
    <transmission name="trans_kinova_joint_2">
        <type>transmission_interface/SimpleTransmission</type>
        <joint name="kinova_joint_2">
            <hardwareInterface>hardware_interface/EffortJointInterface</hardwareInterface>
        </joint>
        <actuator name="kinova_joint_2_motor">
            <hardwareInterface>hardware_interface/EffortJointInterface</hardwareInterface>
            <mechanicalReduction>1</mechanicalReduction>
        </actuator>
    </transmission>
    <transmission name="trans_kinova_joint_3">
        <type>transmission_interface/SimpleTransmission</type>
        <joint name="kinova_joint_3">
            <hardwareInterface>hardware_interface/EffortJointInterface</hardwareInterface>
        </joint>
        <actuator name="kinova_joint_3_motor">
            <hardwareInterface>hardware_interface/EffortJointInterface</hardwareInterface>
            <mechanicalReduction>1</mechanicalReduction>
        </actuator>
    </transmission>
    <transmission name="trans_kinova_joint_4">
        <type>transmission_interface/SimpleTransmission</type>
        <joint name="kinova_joint_4">
            <hardwareInterface>hardware_interface/EffortJointInterface</hardwareInterface>
        </joint>
        <actuator name="kinova_joint_4_motor">
            <hardwareInterface>hardware_interface/EffortJointInterface</hardwareInterface>
            <mechanicalReduction>1</mechanicalReduction>
        </actuator>
    </transmission>
    <transmission name="trans_kinova_joint_5">
        <type>transmission_interface/SimpleTransmission</type>
        <joint name="kinova_joint_5">
            <hardwareInterface>hardware_interface/EffortJointInterface</hardwareInterface>
        </joint>
        <actuator name="kinova_joint_5_motor">
            <hardwareInterface>hardware_interface/EffortJointInterface</hardwareInterface>
            <mechanicalReduction>1</mechanicalReduction>
        </actuator>
    </transmission>
    <transmission name="trans_kinova_joint_6">
        <type>transmission_interface/SimpleTransmission</type>
        <joint name="kinova_joint_6">
            <hardwareInterface>hardware_interface/EffortJointInterface</hardwareInterface>
        </joint>
        <actuator name="kinova_joint_6_motor">
            <hardwareInterface>hardware_interface/EffortJointInterface</hardwareInterface>
            <mechanicalReduction>1</mechanicalReduction>
        </actuator>
    </transmission>
    <transmission name="trans_kinova_joint_7">
        <type>transmission_interface/SimpleTransmission</type>
        <joint name="kinova_joint_7">
            <hardwareInterface>hardware_interface/EffortJointInterface</hardwareInterface>
        </joint>
        <actuator name="kinova_joint_7_motor">
            <hardwareInterface>hardware_interface/EffortJointInterface</hardwareInterface>
            <mechanicalReduction>1</mechanicalReduction>
        </actuator>
    </transmission>
    <transmission name="trans_left_inner_knuckle_joint">
        <type>transmission_interface/SimpleTransmission</type>
        <joint name="left_inner_knuckle_joint">
            <hardwareInterface>hardware_interface/EffortJointInterface</hardwareInterface>
        </joint>
        <actuator name="left_inner_knuckle_joint_motor">
            <hardwareInterface>hardware_interface/EffortJointInterface</hardwareInterface>
            <mechanicalReduction>1</mechanicalReduction>
        </actuator>
    </transmission>
    <transmission name="trans_left_inner_finger_joint">
        <type>transmission_interface/SimpleTransmission</type>
        <joint name="left_inner_finger_joint">
            <hardwareInterface>hardware_interface/EffortJointInterface</hardwareInterface>
        </joint>
        <actuator name="left_inner_finger_joint_motor">
            <hardwareInterface>hardware_interface/EffortJointInterface</hardwareInterface>
            <mechanicalReduction>1</mechanicalReduction>
        </actuator>
    </transmission>
    <transmission name="trans_right_outer_knuckle_joint">
        <type>transmission_interface/SimpleTransmission</type>
        <joint name="right_outer_knuckle_joint">
            <hardwareInterface>hardware_interface/EffortJointInterface</hardwareInterface>
        </joint>
        <actuator name="right_outer_knuckle_joint_motor">
            <hardwareInterface>hardware_interface/EffortJointInterface</hardwareInterface>
            <mechanicalReduction>1</mechanicalReduction>
        </actuator>
    </transmission>
    <transmission name="trans_right_inner_knuckle_joint">
        <type>transmission_interface/SimpleTransmission</type>
        <joint name="right_inner_knuckle_joint">
            <hardwareInterface>hardware_interface/EffortJointInterface</hardwareInterface>
        </joint>
        <actuator name="right_inner_knuckle_joint_motor">
            <hardwareInterface>hardware_interface/EffortJointInterface</hardwareInterface>
            <mechanicalReduction>1</mechanicalReduction>
        </actuator>
    </transmission>
    <transmission name="trans_right_inner_finger_joint">
        <type>transmission_interface/SimpleTransmission</type>
        <joint name="right_inner_finger_joint">
            <hardwareInterface>hardware_interface/EffortJointInterface</hardwareInterface>
        </joint>
        <actuator name="right_inner_finger_joint_motor">
            <hardwareInterface>hardware_interface/EffortJointInterface</hardwareInterface>
            <mechanicalReduction>1</mechanicalReduction>
        </actuator>
    </transmission>
</robot>

